[2016-09-14 13:06:00,894] [ERROR] [__main__-7088.log] [psia_wrap.py:try_get_device_info:486] [try device id: ip:172.20.65.1 pid:7088 threadid:7128 exception fail:HTTPConnectionPool(host='172.20.65.1', port=80): Max retries exceeded with url: /PSIA/System/deviceInfo (Caused by ConnectTimeoutError(<requests.packages.urllib3.connection.HTTPConnection object at 0x00000000063E54A8>, 'Connection to 172.20.65.1 timed out. (connect timeout=5)'))!!!]
